package learn.exceptionhandling;

public class ArithemticException {

	public static void main(String[] args) {
		try {	int number1=2;
		int number2=0;
		int result=number1/number2;
		System.out.println( "divison of two numbers is" +result);
		
		
	} catch(ArithmeticException e){
		System.out.println("uuuresult2");
		}
			
}
	}

